#include <iostream>

using namespace std;


// MathException class to perform exception catching
class MathException {
    public:
        MathException(const string& err)
            : errMsg(err) {}
        string getError() { return errMsg + "\n"; }
    private:
        string errMsg;
};

// ZeroDivide exception class that has inherited MathException class
class zeroDivideError : public MathException {
    public:
        zeroDivideError(const string& err)
            : errMsg(err) {}
    private:
        string errMsg;
};

// NegativeRoot exception class that has inherited MathException class

class NegativeRootError: public mathexception {
    public:
        NegativeRootError(const string& err)
            : errmsg(err) {}
    private:
        string errMsg;
};

int main(void) {
    try {
        int divisor = 0;
        if (divisor == 0)
            throw ZeroDivideError("Trying to divide by 0");
    }
    catch(ZeroDivideError zde) {
        cout << "HAha dividing by zero ðŸ¤£" << endl;
    }
    return 0;
}
